Workbook

Sheet Übersicht
A1: WoW Forever · Lederverarbeitung und Verzauberkunst 1-300 · Rechnung
A2: Stand 12.10.2026 · Mengen: Wowhead-Guides (Classic Era) · Preise: AHledger, Scans aus der Forever-Beta (Horde US, Stufenlimit 30)
A4: Markt | B4: NH | C4: NH = Normal Horde US, PH = PvP Horde US
A5: Preisbasis | B5: jetzt | C5: jetzt = aktueller Median, 30d = Median der letzten 30 Tage
A6: Schwelle dünner Markt | B6: 50 | C6: Preise mit weniger gelisteten Stück gelten als «dünn» (meine Wahl, frei änderbar)
A8: Band (Fertigkeit) | B8: LW Kosten (Gold) | C8: LW in g/s/c | D8: LW Posten ohne Preis | E8: LW Posten dünner Markt | F8: VZ Kosten (Gold) | G8: VZ in g/s/c | H8: VZ Posten ohne Preis | I8: VZ Posten dünner Markt | J8: LW + VZ (Gold)
A9: 1-100 | B9: =SUMIFS(Bedarf!$H$3:$H$85,Bedarf!$A$3:$A$85,"LW",Bedarf!$B$3:$B$85,$A9)/100 -> 1.424 | C9: =IF(B9="","",INT(ROUND(B9*10000,0)/10000)&"g "&INT(MOD(ROUND(B9*10000,0),10000)/100)&"s "&MOD(ROUND(B9*10000,0),100)&"c") -> 1g 42s 40c | D9: =SUMIFS(Bedarf!$I$3:$I$85,Bedarf!$A$3:$A$85,"LW",Bedarf!$B$3:$B$85,$A9) -> 0 | E9: =SUMIFS(Bedarf!$J$3:$J$85,Bedarf!$A$3:$A$85,"LW",Bedarf!$B$3:$B$85,$A9) -> 0 | F9: =SUMIFS(Bedarf!$H$3:$H$85,Bedarf!$A$3:$A$85,"VZ",Bedarf!$B$3:$B$85,$A9)/100 -> 1.1745 | G9: =IF(F9="","",INT(ROUND(F9*10000,0)/10000)&"g "&INT(MOD(ROUND(F9*10000,0),10000)/100)&"s "&MOD(ROUND(F9*10000,0),100)&"c") -> 1g 17s 45c | H9: =SUMIFS(Bedarf!$I$3:$I$85,Bedarf!$A$3:$A$85,"VZ",Bedarf!$B$3:$B$85,$A9) -> 1 | I9: =SUMIFS(Bedarf!$J$3:$J$85,Bedarf!$A$3:$A$85,"VZ",Bedarf!$B$3:$B$85,$A9) -> 0 | J9: =B9+F9 -> 2.5985
A10: 100-150 | B10: =SUMIFS(Bedarf!$H$3:$H$85,Bedarf!$A$3:$A$85,"LW",Bedarf!$B$3:$B$85,$A10)/100 -> 5.1228 | C10: =IF(B10="","",INT(ROUND(B10*10000,0)/10000)&"g "&INT(MOD(ROUND(B10*10000,0),10000)/100)&"s "&MOD(ROUND(B10*10000,0),100)&"c") -> 5g 12s 28c | D10: =SUMIFS(Bedarf!$I$3:$I$85,Bedarf!$A$3:$A$85,"LW",Bedarf!$B$3:$B$85,$A10) -> 0 | E10: =SUMIFS(Bedarf!$J$3:$J$85,Bedarf!$A$3:$A$85,"LW",Bedarf!$B$3:$B$85,$A10) -> 0 | F10: =SUMIFS(Bedarf!$H$3:$H$85,Bedarf!$A$3:$A$85,"VZ",Bedarf!$B$3:$B$85,$A10)/100 -> 4.964 | G10: =IF(F10="","",INT(ROUND(F10*10000,0)/10000)&"g "&INT(MOD(ROUND(F10*10000,0),10000)/100)&"s "&MOD(ROUND(F10*10000,0),100)&"c") -> 4g 96s 40c | H10: =SUMIFS(Bedarf!$I$3:$I$85,Bedarf!$A$3:$A$85,"VZ",Bedarf!$B$3:$B$85,$A10) -> 0 | I10: =SUMIFS(Bedarf!$J$3:$J$85,Bedarf!$A$3:$A$85,"VZ",Bedarf!$B$3:$B$85,$A10) -> 0 | J10: =B10+F10 -> 10.0868
A11: 150-200 | B11: =SUMIFS(Bedarf!$H$3:$H$85,Bedarf!$A$3:$A$85,"LW",Bedarf!$B$3:$B$85,$A11)/100 -> 36.3315 | C11: =IF(B11="","",INT(ROUND(B11*10000,0)/10000)&"g "&INT(MOD(ROUND(B11*10000,0),10000)/100)&"s "&MOD(ROUND(B11*10000,0),100)&"c") -> 36g 33s 15c | D11: =SUMIFS(Bedarf!$I$3:$I$85,Bedarf!$A$3:$A$85,"LW",Bedarf!$B$3:$B$85,$A11) -> 0 | E11: =SUMIFS(Bedarf!$J$3:$J$85,Bedarf!$A$3:$A$85,"LW",Bedarf!$B$3:$B$85,$A11) -> 0 | F11: =SUMIFS(Bedarf!$H$3:$H$85,Bedarf!$A$3:$A$85,"VZ",Bedarf!$B$3:$B$85,$A11)/100 -> 12.5645 | G11: =IF(F11="","",INT(ROUND(F11*10000,0)/10000)&"g "&INT(MOD(ROUND(F11*10000,0),10000)/100)&"s "&MOD(ROUND(F11*10000,0),100)&"c") -> 12g 56s 45c | H11: =SUMIFS(Bedarf!$I$3:$I$85,Bedarf!$A$3:$A$85,"VZ",Bedarf!$B$3:$B$85,$A11) -> 0 | I11: =SUMIFS(Bedarf!$J$3:$J$85,Bedarf!$A$3:$A$85,"VZ",Bedarf!$B$3:$B$85,$A11) -> 2 | J11: =B11+F11 -> 48.896
A12: 200-250 | B12: =SUMIFS(Bedarf!$H$3:$H$85,Bedarf!$A$3:$A$85,"LW",Bedarf!$B$3:$B$85,$A12)/100 -> 161.7865 | C12: =IF(B12="","",INT(ROUND(B12*10000,0)/10000)&"g "&INT(MOD(ROUND(B12*10000,0),10000)/100)&"s "&MOD(ROUND(B12*10000,0),100)&"c") -> 161g 78s 65c | D12: =SUMIFS(Bedarf!$I$3:$I$85,Bedarf!$A$3:$A$85,"LW",Bedarf!$B$3:$B$85,$A12) -> 0 | E12: =SUMIFS(Bedarf!$J$3:$J$85,Bedarf!$A$3:$A$85,"LW",Bedarf!$B$3:$B$85,$A12) -> 0 | F12: =SUMIFS(Bedarf!$H$3:$H$85,Bedarf!$A$3:$A$85,"VZ",Bedarf!$B$3:$B$85,$A12)/100 -> 68.9352 | G12: =IF(F12="","",INT(ROUND(F12*10000,0)/10000)&"g "&INT(MOD(ROUND(F12*10000,0),10000)/100)&"s "&MOD(ROUND(F12*10000,0),100)&"c") -> 68g 93s 52c | H12: =SUMIFS(Bedarf!$I$3:$I$85,Bedarf!$A$3:$A$85,"VZ",Bedarf!$B$3:$B$85,$A12) -> 0 | I12: =SUMIFS(Bedarf!$J$3:$J$85,Bedarf!$A$3:$A$85,"VZ",Bedarf!$B$3:$B$85,$A12) -> 3 | J12: =B12+F12 -> 230.7217
A13: 250-300 | B13: =SUMIFS(Bedarf!$H$3:$H$85,Bedarf!$A$3:$A$85,"LW",Bedarf!$B$3:$B$85,$A13)/100 -> 108.1272 | C13: =IF(B13="","",INT(ROUND(B13*10000,0)/10000)&"g "&INT(MOD(ROUND(B13*10000,0),10000)/100)&"s "&MOD(ROUND(B13*10000,0),100)&"c") -> 108g 12s 72c | D13: =SUMIFS(Bedarf!$I$3:$I$85,Bedarf!$A$3:$A$85,"LW",Bedarf!$B$3:$B$85,$A13) -> 0 | E13: =SUMIFS(Bedarf!$J$3:$J$85,Bedarf!$A$3:$A$85,"LW",Bedarf!$B$3:$B$85,$A13) -> 0 | F13: =SUMIFS(Bedarf!$H$3:$H$85,Bedarf!$A$3:$A$85,"VZ",Bedarf!$B$3:$B$85,$A13)/100 -> 1536.32 | G13: =IF(F13="","",INT(ROUND(F13*10000,0)/10000)&"g "&INT(MOD(ROUND(F13*10000,0),10000)/100)&"s "&MOD(ROUND(F13*10000,0),100)&"c") -> 1536g 32s 0c | H13: =SUMIFS(Bedarf!$I$3:$I$85,Bedarf!$A$3:$A$85,"VZ",Bedarf!$B$3:$B$85,$A13) -> 3 | I13: =SUMIFS(Bedarf!$J$3:$J$85,Bedarf!$A$3:$A$85,"VZ",Bedarf!$B$3:$B$85,$A13) -> 8 | J13: =B13+F13 -> 1644.4472
A14: Summe 1-300 | B14: =SUM(B9:B13) -> 312.792 | C14: =IF(B14="","",INT(ROUND(B14*10000,0)/10000)&"g "&INT(MOD(ROUND(B14*10000,0),10000)/100)&"s "&MOD(ROUND(B14*10000,0),100)&"c") -> 312g 79s 20c | D14: =SUM(D9:D13) -> 0 | E14: =SUM(E9:E13) -> 0 | F14: =SUM(F9:F13) -> 1623.9582 | G14: =IF(F14="","",INT(ROUND(F14*10000,0)/10000)&"g "&INT(MOD(ROUND(F14*10000,0),10000)/100)&"s "&MOD(ROUND(F14*10000,0),100)&"c") -> 1623g 95s 82c | H14: =SUM(H9:H13) -> 4 | I14: =SUM(I9:I13) -> 13 | J14: =SUM(J9:J13) -> 1936.7502
A15: davon 1-200 | B15: =SUM(B9:B11) -> 42.8783 | C15: =IF(B15="","",INT(ROUND(B15*10000,0)/10000)&"g "&INT(MOD(ROUND(B15*10000,0),10000)/100)&"s "&MOD(ROUND(B15*10000,0),100)&"c") -> 42g 87s 83c | F15: =SUM(F9:F11) -> 18.703 | G15: =IF(F15="","",INT(ROUND(F15*10000,0)/10000)&"g "&INT(MOD(ROUND(F15*10000,0),10000)/100)&"s "&MOD(ROUND(F15*10000,0),100)&"c") -> 18g 70s 30c | J15: =B15+F15 -> 61.5813
A16: VZ-Material aus eigener Entzauberung der LW-Teile (Wert, Gold) | F16: =Kreislauf!H59 -> 201.58456 | G16: =IF(F16="","",INT(ROUND(F16*10000,0)/10000)&"g "&INT(MOD(ROUND(F16*10000,0),10000)/100)&"s "&MOD(ROUND(F16*10000,0),100)&"c") -> 201g 58s 46c
A17: VZ netto zu kaufen (Gold) | F17: =F14-F16 -> 1422.3736 | G17: =IF(F17="","",INT(ROUND(F17*10000,0)/10000)&"g "&INT(MOD(ROUND(F17*10000,0),10000)/100)&"s "&MOD(ROUND(F17*10000,0),100)&"c") -> 1422g 37s 36c
A18: LW + VZ netto (Gold) | J18: =B14+F17 -> 1735.1656
A20: So liest du das Blatt
A21: Gelb = hier änderst du: Markt (B4), Preisbasis (B5), Schwelle (B6); im Blatt Preise die Spalte «Eigener Preis»; im Blatt Kreislauf die Chancen.
A22: Beispiel: Am 04.11. kostet Medium Leather 3s 50c → im Blatt Preise bei Medium Leather in Spalte K «3.5» eintragen. Alles rechnet neu.
A23: Blau = Werte aus Quellen (Wowhead, AHledger, Blizzard Dev Notes). Grün = Bezug auf ein anderes Blatt. Schwarz = Formel.
A24: Die Mengen sind Wowheads Classic-Era-Routen. Forever weicht ab (LW-Rezepte rund 25 Punkte tiefer, einige VZ-Rezepte der Route fehlen in Forever). Siehe Bemerkungen im Blatt Bedarf.
A25: Posten ohne Preis zählen als 0: Die Summe ist dann zu tief. «Dünner Markt» = wenige gelistete Stück, der Preis ist ein Zufallswert.
A27: Materialliste (Summe der Routenschritte; zum Vergleich Wowheads eigene Einkaufsliste)
A28: Material | B28: Beruf | C28: Menge Route | D28: Menge Wowhead-Liste | E28: Rechenpreis (s) | F28: Kosten (Gold) | G28: Hinweis
A29: Ruined Leather Scraps | B29: LW | C29: =SUMIFS(Bedarf!$F$3:$F$85,Bedarf!$A$3:$A$85,B29,Bedarf!$E$3:$E$85,A29) -> 90 | D29: 90 | E29: =IFERROR(INDEX(Preise!$L$3:$L$53,MATCH(A29,Preise!$A$3:$A$53,0)),"") -> 0.25 | F29: =IF(E29="","",C29*E29/100) -> 0.225 | G29: =IFERROR(INDEX(Preise!$M$3:$M$53,MATCH(A29,Preise!$A$3:$A$53,0)),"")
A30: Light Leather | B30: LW | C30: =SUMIFS(Bedarf!$F$3:$F$85,Bedarf!$A$3:$A$85,B30,Bedarf!$E$3:$E$85,A30) -> 198 | D30: 198 | E30: =IFERROR(INDEX(Preise!$L$3:$L$53,MATCH(A30,Preise!$A$3:$A$53,0)),"") -> 0.5 | F30: =IF(E30="","",C30*E30/100) -> 0.99 | G30: =IFERROR(INDEX(Preise!$M$3:$M$53,MATCH(A30,Preise!$A$3:$A$53,0)),"")
A31: Light Hide | B31: LW | C31: =SUMIFS(Bedarf!$F$3:$F$85,Bedarf!$A$3:$A$85,B31,Bedarf!$E$3:$E$85,A31) -> 10 | D31: 10 | E31: =IFERROR(INDEX(Preise!$L$3:$L$53,MATCH(A31,Preise!$A$3:$A$53,0)),"") -> 0.69 | F31: =IF(E31="","",C31*E31/100) -> 0.069 | G31: =IFERROR(INDEX(Preise!$M$3:$M$53,MATCH(A31,Preise!$A$3:$A$53,0)),"")
A32: Salt | B32: LW | C32: =SUMIFS(Bedarf!$F$3:$F$85,Bedarf!$A$3:$A$85,B32,Bedarf!$E$3:$E$85,A32) -> 85 | D32: 40 (135) | E32: =IFERROR(INDEX(Preise!$L$3:$L$53,MATCH(A32,Preise!$A$3:$A$53,0)),"") -> 0.5 | F32: =IF(E32="","",C32*E32/100) -> 0.425 | G32: =IFERROR(INDEX(Preise!$M$3:$M$53,MATCH(A32,Preise!$A$3:$A$53,0)),"") -> Händler
A33: Coarse Thread | B33: LW | C33: =SUMIFS(Bedarf!$F$3:$F$85,Bedarf!$A$3:$A$85,B33,Bedarf!$E$3:$E$85,A33) -> 90 | D33: 90 | E33: =IFERROR(INDEX(Preise!$L$3:$L$53,MATCH(A33,Preise!$A$3:$A$53,0)),"") -> 0.1 | F33: =IF(E33="","",C33*E33/100) -> 0.09 | G33: =IFERROR(INDEX(Preise!$M$3:$M$53,MATCH(A33,Preise!$A$3:$A$53,0)),"") -> Händler
A34: Medium Hide | B34: LW | C34: =SUMIFS(Bedarf!$F$3:$F$85,Bedarf!$A$3:$A$85,B34,Bedarf!$E$3:$E$85,A34) -> 15 | D34: 15 | E34: =IFERROR(INDEX(Preise!$L$3:$L$53,MATCH(A34,Preise!$A$3:$A$53,0)),"") -> 8.88 | F34: =IF(E34="","",C34*E34/100) -> 1.332 | G34: =IFERROR(INDEX(Preise!$M$3:$M$53,MATCH(A34,Preise!$A$3:$A$53,0)),"")
A35: Medium Leather | B35: LW | C35: =SUMIFS(Bedarf!$F$3:$F$85,Bedarf!$A$3:$A$85,B35,Bedarf!$E$3:$E$85,A35) -> 113 | D35: 113 | E35: =IFERROR(INDEX(Preise!$L$3:$L$53,MATCH(A35,Preise!$A$3:$A$53,0)),"") -> 1.91 | F35: =IF(E35="","",C35*E35/100) -> 2.1583 | G35: =IFERROR(INDEX(Preise!$M$3:$M$53,MATCH(A35,Preise!$A$3:$A$53,0)),"")
A36: Fine Thread | B36: LW | C36: =SUMIFS(Bedarf!$F$3:$F$85,Bedarf!$A$3:$A$85,B36,Bedarf!$E$3:$E$85,A36) -> 116 | D36: 116 | E36: =IFERROR(INDEX(Preise!$L$3:$L$53,MATCH(A36,Preise!$A$3:$A$53,0)),"") -> 1 | F36: =IF(E36="","",C36*E36/100) -> 1.16 | G36: =IFERROR(INDEX(Preise!$M$3:$M$53,MATCH(A36,Preise!$A$3:$A$53,0)),"") -> Händler
A37: Gray Dye | B37: LW | C37: =SUMIFS(Bedarf!$F$3:$F$85,Bedarf!$A$3:$A$85,B37,Bedarf!$E$3:$E$85,A37) -> 37 | D37: 37 | E37: =IFERROR(INDEX(Preise!$L$3:$L$53,MATCH(A37,Preise!$A$3:$A$53,0)),"") -> 3.5 | F37: =IF(E37="","",C37*E37/100) -> 1.295 | G37: =IFERROR(INDEX(Preise!$M$3:$M$53,MATCH(A37,Preise!$A$3:$A$53,0)),"") -> Händler
A38: Heavy Hide | B38: LW | C38: =SUMIFS(Bedarf!$F$3:$F$85,Bedarf!$A$3:$A$85,B38,Bedarf!$E$3:$E$85,A38) -> 20 | D38: 5 (40) | E38: =IFERROR(INDEX(Preise!$L$3:$L$53,MATCH(A38,Preise!$A$3:$A$53,0)),"") -> 35.4 | F38: =IF(E38="","",C38*E38/100) -> 7.08 | G38: =IFERROR(INDEX(Preise!$M$3:$M$53,MATCH(A38,Preise!$A$3:$A$53,0)),"")
A39: Heavy Leather | B39: LW | C39: =SUMIFS(Bedarf!$F$3:$F$85,Bedarf!$A$3:$A$85,B39,Bedarf!$E$3:$E$85,A39) -> 230 | D39: 230 | E39: =IFERROR(INDEX(Preise!$L$3:$L$53,MATCH(A39,Preise!$A$3:$A$53,0)),"") -> 11.98 | F39: =IF(E39="","",C39*E39/100) -> 27.554 | G39: =IFERROR(INDEX(Preise!$M$3:$M$53,MATCH(A39,Preise!$A$3:$A$53,0)),"")
A40: Silken Thread | B40: LW | C40: =SUMIFS(Bedarf!$F$3:$F$85,Bedarf!$A$3:$A$85,B40,Bedarf!$E$3:$E$85,A40) -> 132 | D40: 122 | E40: =IFERROR(INDEX(Preise!$L$3:$L$53,MATCH(A40,Preise!$A$3:$A$53,0)),"") -> 5 | F40: =IF(E40="","",C40*E40/100) -> 6.6 | G40: =IFERROR(INDEX(Preise!$M$3:$M$53,MATCH(A40,Preise!$A$3:$A$53,0)),"") -> Händler
A41: Thick Leather | B41: LW | C41: =SUMIFS(Bedarf!$F$3:$F$85,Bedarf!$A$3:$A$85,B41,Bedarf!$E$3:$E$85,A41) -> 435 | D41: 435 | E41: =IFERROR(INDEX(Preise!$L$3:$L$53,MATCH(A41,Preise!$A$3:$A$53,0)),"") -> 35.79 | F41: =IF(E41="","",C41*E41/100) -> 155.6865 | G41: =IFERROR(INDEX(Preise!$M$3:$M$53,MATCH(A41,Preise!$A$3:$A$53,0)),"")
A42: Rugged Leather | B42: LW | C42: =SUMIFS(Bedarf!$F$3:$F$85,Bedarf!$A$3:$A$85,B42,Bedarf!$E$3:$E$85,A42) -> 436 | D42: 436 | E42: =IFERROR(INDEX(Preise!$L$3:$L$53,MATCH(A42,Preise!$A$3:$A$53,0)),"") -> 19.02 | F42: =IF(E42="","",C42*E42/100) -> 82.9272 | G42: =IFERROR(INDEX(Preise!$M$3:$M$53,MATCH(A42,Preise!$A$3:$A$53,0)),"")
A43: Black Dye | B43: LW | C43: =SUMIFS(Bedarf!$F$3:$F$85,Bedarf!$A$3:$A$85,B43,Bedarf!$E$3:$E$85,A43) -> 42 | D43: 42 | E43: =IFERROR(INDEX(Preise!$L$3:$L$53,MATCH(A43,Preise!$A$3:$A$53,0)),"") -> 10 | F43: =IF(E43="","",C43*E43/100) -> 4.2 | G43: =IFERROR(INDEX(Preise!$M$3:$M$53,MATCH(A43,Preise!$A$3:$A$53,0)),"") -> Händler
A44: Rune Thread | B44: LW | C44: =SUMIFS(Bedarf!$F$3:$F$85,Bedarf!$A$3:$A$85,B44,Bedarf!$E$3:$E$85,A44) -> 42 | D44: 42 | E44: =IFERROR(INDEX(Preise!$L$3:$L$53,MATCH(A44,Preise!$A$3:$A$53,0)),"") -> 50 | F44: =IF(E44="","",C44*E44/100) -> 21 | G44: =IFERROR(INDEX(Preise!$M$3:$M$53,MATCH(A44,Preise!$A$3:$A$53,0)),"") -> Händler
...

Sheet Preise
A1: Preise in Silber (1 Gold = 100 Silber, 1 Silber = 100 Kupfer). Marktpreise: AHledger, Forever-Beta, Horde US. Gelbe Spalte K: eigener Preis überschreibt alles.
A2: Material | B2: Beruf | C2: Händlerpreis (s) | D2: NH Median (s) | E2: PH Median (s) | F2: NH 30 Tage (s) | G2: PH 30 Tage (s) | H2: NH gelistet (Stück) | I2: PH gelistet (Stück) | J2: Stand Seite | K2: Eigener Preis (s) | L2: Rechenpreis (s) | M2: Hinweis | N2: Quelle | O2: Bemerkung
A3: Ruined Leather Scraps | B3: LW | D3: 0.25 | E3: 0.28 | F3: 0.28 | G3: 0.4 | H3: 2553 | I3: 4407 | J3: 12.10. | L3: =IF(K3<>"",K3,IF(C3<>"",C3,IF(Übersicht!$B$4="NH",IF(Übersicht!$B$5="jetzt",IF(D3="","",D3),IF(F3="","",F3)),IF(Übersicht!$B$5="jetzt",IF(E3="","",E3),IF(G3="","",G3))))) -> 0.25 | M3: =IF(L3="","kein Preis",IF(K3<>"","eigener Preis",IF(C3<>"","Händler",IF(IF(Übersicht!$B$4="NH",H3,I3)<Übersicht!$B$6,"dünn","")))) | N3: https://ahledger.com/items/2934-ruined-leather-scraps
A4: Light Leather | B4: LW | D4: 0.5 | E4: 0.68 | F4: 0.79 | G4: 1.09 | H4: 2729 | I4: 5335 | J4: 12.10. | L4: =IF(K4<>"",K4,IF(C4<>"",C4,IF(Übersicht!$B$4="NH",IF(Übersicht!$B$5="jetzt",IF(D4="","",D4),IF(F4="","",F4)),IF(Übersicht!$B$5="jetzt",IF(E4="","",E4),IF(G4="","",G4))))) -> 0.5 | M4: =IF(L4="","kein Preis",IF(K4<>"","eigener Preis",IF(C4<>"","Händler",IF(IF(Übersicht!$B$4="NH",H4,I4)<Übersicht!$B$6,"dünn","")))) | N4: https://ahledger.com/items/2318-light-leather
A5: Medium Leather | B5: LW | D5: 1.91 | E5: 2.1 | F5: 2.56 | G5: 2.29 | H5: 3562 | I5: 2894 | J5: 12.10. | L5: =IF(K5<>"",K5,IF(C5<>"",C5,IF(Übersicht!$B$4="NH",IF(Übersicht!$B$5="jetzt",IF(D5="","",D5),IF(F5="","",F5)),IF(Übersicht!$B$5="jetzt",IF(E5="","",E5),IF(G5="","",G5))))) -> 1.91 | M5: =IF(L5="","kein Preis",IF(K5<>"","eigener Preis",IF(C5<>"","Händler",IF(IF(Übersicht!$B$4="NH",H5,I5)<Übersicht!$B$6,"dünn","")))) | N5: https://ahledger.com/items/2319-medium-leather
A6: Heavy Leather | B6: LW | D6: 11.98 | E6: 11 | F6: 12.7 | G6: 12.23 | H6: 2372 | I6: 1784 | J6: 08.10. | L6: =IF(K6<>"",K6,IF(C6<>"",C6,IF(Übersicht!$B$4="NH",IF(Übersicht!$B$5="jetzt",IF(D6="","",D6),IF(F6="","",F6)),IF(Übersicht!$B$5="jetzt",IF(E6="","",E6),IF(G6="","",G6))))) -> 11.98 | M6: =IF(L6="","kein Preis",IF(K6<>"","eigener Preis",IF(C6<>"","Händler",IF(IF(Übersicht!$B$4="NH",H6,I6)<Übersicht!$B$6,"dünn","")))) | N6: https://ahledger.com/items/4234-heavy-leather | O6: Marktseite 12.10.: NH 9.40 s, PH 9.13 s
A7: Thick Leather | B7: LW | D7: 35.79 | E7: 62 | F7: 40.2 | G7: 48.48 | H7: 348 | I7: 264 | J7: 12.10. | L7: =IF(K7<>"",K7,IF(C7<>"",C7,IF(Übersicht!$B$4="NH",IF(Übersicht!$B$5="jetzt",IF(D7="","",D7),IF(F7="","",F7)),IF(Übersicht!$B$5="jetzt",IF(E7="","",E7),IF(G7="","",G7))))) -> 35.79 | M7: =IF(L7="","kein Preis",IF(K7<>"","eigener Preis",IF(C7<>"","Händler",IF(IF(Übersicht!$B$4="NH",H7,I7)<Übersicht!$B$6,"dünn","")))) | N7: https://ahledger.com/items/4304-thick-leather
A8: Rugged Leather | B8: LW | D8: 19.02 | E8: 5 | F8: 9.8 | G8: 7.78 | H8: 214 | I8: 135 | J8: 05.10. | L8: =IF(K8<>"",K8,IF(C8<>"",C8,IF(Übersicht!$B$4="NH",IF(Übersicht!$B$5="jetzt",IF(D8="","",D8),IF(F8="","",F8)),IF(Übersicht!$B$5="jetzt",IF(E8="","",E8),IF(G8="","",G8))))) -> 19.02 | M8: =IF(L8="","kein Preis",IF(K8<>"","eigener Preis",IF(C8<>"","Händler",IF(IF(Übersicht!$B$4="NH",H8,I8)<Übersicht!$B$6,"dünn","")))) | N8: https://ahledger.com/items/8170-rugged-leather | O8: Beta bis Stufe 30: kaum Angebot
A9: Light Hide | B9: LW | D9: 0.69 | E9: 0.56 | F9: 0.78 | G9: 0.64 | H9: 189 | I9: 793 | J9: 09.10. | L9: =IF(K9<>"",K9,IF(C9<>"",C9,IF(Übersicht!$B$4="NH",IF(Übersicht!$B$5="jetzt",IF(D9="","",D9),IF(F9="","",F9)),IF(Übersicht!$B$5="jetzt",IF(E9="","",E9),IF(G9="","",G9))))) -> 0.69 | M9: =IF(L9="","kein Preis",IF(K9<>"","eigener Preis",IF(C9<>"","Händler",IF(IF(Übersicht!$B$4="NH",H9,I9)<Übersicht!$B$6,"dünn","")))) | N9: https://ahledger.com/items/783-light-hide
A10: Medium Hide | B10: LW | D10: 8.88 | E10: 7.32 | F10: 9.12 | G10: 7.78 | H10: 221 | I10: 667 | J10: 30.09. | L10: =IF(K10<>"",K10,IF(C10<>"",C10,IF(Übersicht!$B$4="NH",IF(Übersicht!$B$5="jetzt",IF(D10="","",D10),IF(F10="","",F10)),IF(Übersicht!$B$5="jetzt",IF(E10="","",E10),IF(G10="","",G10))))) -> 8.88 | M10: =IF(L10="","kein Preis",IF(K10<>"","eigener Preis",IF(C10<>"","Händler",IF(IF(Übersicht!$B$4="NH",H10,I10)<Übersicht!$B$6,"dünn","")))) | N10: https://ahledger.com/items/4232-medium-hide
A11: Heavy Hide | B11: LW | D11: 35.4 | E11: 30.69 | F11: 96.75 | G11: 72.99 | H11: 231 | I11: 279 | J11: 08.10. | L11: =IF(K11<>"",K11,IF(C11<>"",C11,IF(Übersicht!$B$4="NH",IF(Übersicht!$B$5="jetzt",IF(D11="","",D11),IF(F11="","",F11)),IF(Übersicht!$B$5="jetzt",IF(E11="","",E11),IF(G11="","",G11))))) -> 35.4 | M11: =IF(L11="","kein Preis",IF(K11<>"","eigener Preis",IF(C11<>"","Händler",IF(IF(Übersicht!$B$4="NH",H11,I11)<Übersicht!$B$6,"dünn","")))) | N11: https://ahledger.com/items/4235-heavy-hide
A12: Salt | B12: LW | C12: 0.5 | D12: 1 | E12: 0.7 | F12: 0.82 | G12: 0.82 | H12: 64 | I12: 493 | J12: 05.10. | L12: =IF(K12<>"",K12,IF(C12<>"",C12,IF(Übersicht!$B$4="NH",IF(Übersicht!$B$5="jetzt",IF(D12="","",D12),IF(F12="","",F12)),IF(Übersicht!$B$5="jetzt",IF(E12="","",E12),IF(G12="","",G12))))) -> 0.5 | M12: =IF(L12="","kein Preis",IF(K12<>"","eigener Preis",IF(C12<>"","Händler",IF(IF(Übersicht!$B$4="NH",H12,I12)<Übersicht!$B$6,"dünn","")))) -> Händler | N12: https://ahledger.com/items/4289-salt | O12: Händlerpreis laut AHledger
A13: Coarse Thread | B13: LW | C13: 0.1 | D13: 0.17 | E13: 0.22 | F13: 0.34 | G13: 0.34 | H13: 1596 | I13: 1796 | J13: 12.10. | L13: =IF(K13<>"",K13,IF(C13<>"",C13,IF(Übersicht!$B$4="NH",IF(Übersicht!$B$5="jetzt",IF(D13="","",D13),IF(F13="","",F13)),IF(Übersicht!$B$5="jetzt",IF(E13="","",E13),IF(G13="","",G13))))) -> 0.1 | M13: =IF(L13="","kein Preis",IF(K13<>"","eigener Preis",IF(C13<>"","Händler",IF(IF(Übersicht!$B$4="NH",H13,I13)<Übersicht!$B$6,"dünn","")))) -> Händler | N13: https://ahledger.com/items/2320-coarse-thread | O13: Händlerpreis laut warcraft.wiki.gg (Version nicht angegeben)
A14: Fine Thread | B14: LW | C14: 1 | D14: 1.87 | E14: 1.48 | F14: 1.55 | G14: 1.44 | H14: 163 | I14: 1126 | J14: 03.10. | L14: =IF(K14<>"",K14,IF(C14<>"",C14,IF(Übersicht!$B$4="NH",IF(Übersicht!$B$5="jetzt",IF(D14="","",D14),IF(F14="","",F14)),IF(Übersicht!$B$5="jetzt",IF(E14="","",E14),IF(G14="","",G14))))) -> 1 | M14: =IF(L14="","kein Preis",IF(K14<>"","eigener Preis",IF(C14<>"","Händler",IF(IF(Übersicht!$B$4="NH",H14,I14)<Übersicht!$B$6,"dünn","")))) -> Händler | N14: https://ahledger.com/items/2321-fine-thread | O14: Händlerpreis laut AHledger und warcraft.wiki.gg
A15: Silken Thread | B15: LW | C15: 5 | D15: 10 | E15: 8.5 | F15: 10 | G15: 8.52 | H15: 22 | I15: 48 | J15: 27.09. | L15: =IF(K15<>"",K15,IF(C15<>"",C15,IF(Übersicht!$B$4="NH",IF(Übersicht!$B$5="jetzt",IF(D15="","",D15),IF(F15="","",F15)),IF(Übersicht!$B$5="jetzt",IF(E15="","",E15),IF(G15="","",G15))))) -> 5 | M15: =IF(L15="","kein Preis",IF(K15<>"","eigener Preis",IF(C15<>"","Händler",IF(IF(Übersicht!$B$4="NH",H15,I15)<Übersicht!$B$6,"dünn","")))) -> Händler | N15: https://ahledger.com/items/4291-silken-thread | O15: Händlerpreis laut warcraft.wiki.gg (Version nicht angegeben, für Forever ungeprüft)
A16: Rune Thread | B16: LW | C16: 50 | E16: 99.99 | F16: 19 | G16: 63 | H16: 0 | I16: 1 | J16: 05.10. | L16: =IF(K16<>"",K16,IF(C16<>"",C16,IF(Übersicht!$B$4="NH",IF(Übersicht!$B$5="jetzt",IF(D16="","",D16),IF(F16="","",F16)),IF(Übersicht!$B$5="jetzt",IF(E16="","",E16),IF(G16="","",G16))))) -> 50 | M16: =IF(L16="","kein Preis",IF(K16<>"","eigener Preis",IF(C16<>"","Händler",IF(IF(Übersicht!$B$4="NH",H16,I16)<Übersicht!$B$6,"dünn","")))) -> Händler | N16: https://ahledger.com/items/14341-rune-thread | O16: Händlerpreis laut AHledger
A17: Gray Dye | B17: LW | C17: 3.5 | D17: 4.69 | E17: 2.99 | F17: 6.16 | G17: 5.54 | H17: 28 | I17: 20 | J17: 05.10. | L17: =IF(K17<>"",K17,IF(C17<>"",C17,IF(Übersicht!$B$4="NH",IF(Übersicht!$B$5="jetzt",IF(D17="","",D17),IF(F17="","",F17)),IF(Übersicht!$B$5="jetzt",IF(E17="","",E17),IF(G17="","",G17))))) -> 3.5 | M17: =IF(L17="","kein Preis",IF(K17<>"","eigener Preis",IF(C17<>"","Händler",IF(IF(Übersicht!$B$4="NH",H17,I17)<Übersicht!$B$6,"dünn","")))) -> Händler | N17: https://ahledger.com/items/4340-gray-dye | O17: Händlerpreis laut AHledger
A18: Black Dye | B18: LW | C18: 10 | D18: 20 | E18: 24 | F18: 5.7 | G18: 8 | H18: 20 | I18: 21 | J18: 05.10. | L18: =IF(K18<>"",K18,IF(C18<>"",C18,IF(Übersicht!$B$4="NH",IF(Übersicht!$B$5="jetzt",IF(D18="","",D18),IF(F18="","",F18)),IF(Übersicht!$B$5="jetzt",IF(E18="","",E18),IF(G18="","",G18))))) -> 10 | M18: =IF(L18="","kein Preis",IF(K18<>"","eigener Preis",IF(C18<>"","Händler",IF(IF(Übersicht!$B$4="NH",H18,I18)<Übersicht!$B$6,"dünn","")))) -> Händler | N18: https://ahledger.com/items/2325-black-dye | O18: Händlerpreis laut AHledger
A19: Strange Dust | B19: VZ | D19: 0.84 | E19: 0.65 | F19: 2.42 | G19: 2.53 | H19: 7166 | I19: 3403 | J19: 12.10. | L19: =IF(K19<>"",K19,IF(C19<>"",C19,IF(Übersicht!$B$4="NH",IF(Übersicht!$B$5="jetzt",IF(D19="","",D19),IF(F19="","",F19)),IF(Übersicht!$B$5="jetzt",IF(E19="","",E19),IF(G19="","",G19))))) -> 0.84 | M19: =IF(L19="","kein Preis",IF(K19<>"","eigener Preis",IF(C19<>"","Händler",IF(IF(Übersicht!$B$4="NH",H19,I19)<Übersicht!$B$6,"dünn","")))) | N19: https://ahledger.com/items/10940-strange-dust
A20: Soul Dust | B20: VZ | D20: 7.21 | E20: 5.8 | F20: 8.53 | G20: 9.04 | H20: 1555 | I20: 2780 | J20: 12.10. | L20: =IF(K20<>"",K20,IF(C20<>"",C20,IF(Übersicht!$B$4="NH",IF(Übersicht!$B$5="jetzt",IF(D20="","",D20),IF(F20="","",F20)),IF(Übersicht!$B$5="jetzt",IF(E20="","",E20),IF(G20="","",G20))))) -> 7.21 | M20: =IF(L20="","kein Preis",IF(K20<>"","eigener Preis",IF(C20<>"","Händler",IF(IF(Übersicht!$B$4="NH",H20,I20)<Übersicht!$B$6,"dünn","")))) | N20: https://ahledger.com/items/11083-soul-dust
A21: Vision Dust | B21: VZ | D21: 19.71 | E21: 24.49 | F21: 37.3 | G21: 45.98 | H21: 637 | I21: 738 | J21: 12.10. | L21: =IF(K21<>"",K21,IF(C21<>"",C21,IF(Übersicht!$B$4="NH",IF(Übersicht!$B$5="jetzt",IF(D21="","",D21),IF(F21="","",F21)),IF(Übersicht!$B$5="jetzt",IF(E21="","",E21),IF(G21="","",G21))))) -> 19.71 | M21: =IF(L21="","kein Preis",IF(K21<>"","eigener Preis",IF(C21<>"","Händler",IF(IF(Übersicht!$B$4="NH",H21,I21)<Übersicht!$B$6,"dünn","")))) | N21: https://ahledger.com/items/11137-vision-dust
A22: Dream Dust | B22: VZ | D22: 58 | E22: 48.55 | F22: 46.43 | G22: 65.44 | H22: 47 | I22: 592 | J22: 12.10. | L22: =IF(K22<>"",K22,IF(C22<>"",C22,IF(Übersicht!$B$4="NH",IF(Übersicht!$B$5="jetzt",IF(D22="","",D22),IF(F22="","",F22)),IF(Übersicht!$B$5="jetzt",IF(E22="","",E22),IF(G22="","",G22))))) -> 58 | M22: =IF(L22="","kein Preis",IF(K22<>"","eigener Preis",IF(C22<>"","Händler",IF(IF(Übersicht!$B$4="NH",H22,I22)<Übersicht!$B$6,"dünn","")))) -> dünn | N22: https://ahledger.com/items/11176-dream-dust
A23: Illusion Dust | B23: VZ | D23: 1000 | F23: 1000 | G23: 481 | H23: 2 | I23: 0 | J23: 12.10. | L23: =IF(K23<>"",K23,IF(C23<>"",C23,IF(Übersicht!$B$4="NH",IF(Übersicht!$B$5="jetzt",IF(D23="","",D23),IF(F23="","",F23)),IF(Übersicht!$B$5="jetzt",IF(E23="","",E23),IF(G23="","",G23))))) -> 1000 | M23: =IF(L23="","kein Preis",IF(K23<>"","eigener Preis",IF(C23<>"","Händler",IF(IF(Übersicht!$B$4="NH",H23,I23)<Übersicht!$B$6,"dünn","")))) -> dünn | N23: https://ahledger.com/items/16204-illusion-dust | O23: NH: 2 Stück, Ausnahmewert
A24: Lesser Magic Essence | B24: VZ | D24: 0.69 | E24: 3.9 | F24: 7.35 | G24: 7.3 | H24: 2563 | I24: 18247 | J24: 03.10. | L24: =IF(K24<>"",K24,IF(C24<>"",C24,IF(Übersicht!$B$4="NH",IF(Übersicht!$B$5="jetzt",IF(D24="","",D24),IF(F24="","",F24)),IF(Übersicht!$B$5="jetzt",IF(E24="","",E24),IF(G24="","",G24))))) -> 0.69 | M24: =IF(L24="","kein Preis",IF(K24<>"","eigener Preis",IF(C24<>"","Händler",IF(IF(Übersicht!$B$4="NH",H24,I24)<Übersicht!$B$6,"dünn","")))) | N24: https://ahledger.com/items/10938-lesser-magic-essence
A25: Greater Magic Essence | B25: VZ | D25: 1.96 | E25: 1.89 | F25: 21.58 | G25: 21.36 | H25: 898 | I25: 424 | J25: 09.10. | L25: =IF(K25<>"",K25,IF(C25<>"",C25,IF(Übersicht!$B$4="NH",IF(Übersicht!$B$5="jetzt",IF(D25="","",D25),IF(F25="","",F25)),IF(Übersicht!$B$5="jetzt",IF(E25="","",E25),IF(G25="","",G25))))) -> 1.96 | M25: =IF(L25="","kein Preis",IF(K25<>"","eigener Preis",IF(C25<>"","Händler",IF(IF(Übersicht!$B$4="NH",H25,I25)<Übersicht!$B$6,"dünn","")))) | N25: https://ahledger.com/items/10939-greater-magic-essence
A26: Lesser Astral Essence | B26: VZ | D26: 6.04 | E26: 5.79 | F26: 9.42 | G26: 8.11 | H26: 681 | I26: 404 | J26: 30.09. | L26: =IF(K26<>"",K26,IF(C26<>"",C26,IF(Übersicht!$B$4="NH",IF(Übersicht!$B$5="jetzt",IF(D26="","",D26),IF(F26="","",F26)),IF(Übersicht!$B$5="jetzt",IF(E26="","",E26),IF(G26="","",G26))))) -> 6.04 | M26: =IF(L26="","kein Preis",IF(K26<>"","eigener Preis",IF(C26<>"","Händler",IF(IF(Übersicht!$B$4="NH",H26,I26)<Übersicht!$B$6,"dünn","")))) | N26: https://ahledger.com/items/10998-lesser-astral-essence
A27: Greater Astral Essence | B27: VZ | D27: 28.54 | E27: 29.99 | F27: 36.7 | G27: 30.33 | H27: 137 | I27: 102 | J27: 27.09. | L27: =IF(K27<>"",K27,IF(C27<>"",C27,IF(Übersicht!$B$4="NH",IF(Übersicht!$B$5="jetzt",IF(D27="","",D27),IF(F27="","",F27)),IF(Übersicht!$B$5="jetzt",IF(E27="","",E27),IF(G27="","",G27))))) -> 28.54 | M27: =IF(L27="","kein Preis",IF(K27<>"","eigener Preis",IF(C27<>"","Händler",IF(IF(Übersicht!$B$4="NH",H27,I27)<Übersicht!$B$6,"dünn","")))) | N27: https://ahledger.com/items/11082-greater-astral-essence
A28: Lesser Mystic Essence | B28: VZ | D28: 15.96 | E28: 10.99 | F28: 62.09 | G28: 33.56 | H28: 122 | I28: 713 | J28: 12.10. | L28: =IF(K28<>"",K28,IF(C28<>"",C28,IF(Übersicht!$B$4="NH",IF(Übersicht!$B$5="jetzt",IF(D28="","",D28),IF(F28="","",F28)),IF(Übersicht!$B$5="jetzt",IF(E28="","",E28),IF(G28="","",G28))))) -> 15.96 | M28: =IF(L28="","kein Preis",IF(K28<>"","eigener Preis",IF(C28<>"","Händler",IF(IF(Übersicht!$B$4="NH",H28,I28)<Übersicht!$B$6,"dünn","")))) | N28: https://ahledger.com/items/11134-lesser-mystic-essence
A29: Greater Mystic Essence | B29: VZ | D29: 44 | E29: 27.97 | F29: 191.72 | G29: 109.75 | H29: 99 | I29: 110 | J29: 12.10. | L29: =IF(K29<>"",K29,IF(C29<>"",C29,IF(Übersicht!$B$4="NH",IF(Übersicht!$B$5="jetzt",IF(D29="","",D29),IF(F29="","",F29)),IF(Übersicht!$B$5="jetzt",IF(E29="","",E29),IF(G29="","",G29))))) -> 44 | M29: =IF(L29="","kein Preis",IF(K29<>"","eigener Preis",IF(C29<>"","Händler",IF(IF(Übersicht!$B$4="NH",H29,I29)<Übersicht!$B$6,"dünn","")))) | N29: https://ahledger.com/items/11135-greater-mystic-essence
A30: Lesser Nether Essence | B30: VZ | D30: 268.98 | E30: 345.93 | F30: 132.42 | G30: 139.36 | H30: 46 | I30: 67 | J30: 12.10. | L30: =IF(K30<>"",K30,IF(C30<>"",C30,IF(Übersicht!$B$4="NH",IF(Übersicht!$B$5="jetzt",IF(D30="","",D30),IF(F30="","",F30)),IF(Übersicht!$B$5="jetzt",IF(E30="","",E30),IF(G30="","",G30))))) -> 268.98 | M30: =IF(L30="","kein Preis",IF(K30<>"","eigener Preis",IF(C30<>"","Händler",IF(IF(Übersicht!$B$4="NH",H30,I30)<Übersicht!$B$6,"dünn","")))) -> dünn | N30: https://ahledger.com/items/11174-lesser-nether-essence
A31: Greater Nether Essence | B31: VZ | D31: 800 | E31: 1099 | F31: 439.94 | G31: 412.27 | H31: 17 | I31: 17 | J31: 12.10. | L31: =IF(K31<>"",K31,IF(C31<>"",C31,IF(Übersicht!$B$4="NH",IF(Übersicht!$B$5="jetzt",IF(D31="","",D31),IF(F31="","",F31)),IF(Übersicht!$B$5="jetzt",IF(E31="","",E31),IF(G31="","",G31))))) -> 800 | M31: =IF(L31="","kein Preis",IF(K31<>"","eigener Preis",IF(C31<>"","Händler",IF(IF(Übersicht!$B$4="NH",H31,I31)<Übersicht!$B$6,"dünn","")))) -> dünn | N31: https://ahledger.com/items/11175-greater-nether-essence
A32: Lesser Eternal Essence | B32: VZ | D32: 200 | E32: 65 | F32: 500 | G32: 228.06 | H32: 42 | I32: 16 | J32: 12.10. | L32: =IF(K32<>"",K32,IF(C32<>"",C32,IF(Übersicht!$B$4="NH",IF(Übersicht!$B$5="jetzt",IF(D32="","",D32),IF(F32="","",F32)),IF(Übersicht!$B$5="jetzt",IF(E32="","",E32),IF(G32="","",G32))))) -> 200 | M32: =IF(L32="","kein Preis",IF(K32<>"","eigener Preis",IF(C32<>"","Händler",IF(IF(Übersicht!$B$4="NH",H32,I32)<Übersicht!$B$6,"dünn","")))) -> dünn | N32: https://ahledger.com/items/16202-lesser-eternal-essence
A33: Greater Eternal Essence | B33: VZ | E33: 454 | G33: 1001 | H33: 0 | I33: 12 | J33: 12.10. | L33: =IF(K33<>"",K33,IF(C33<>"",C33,IF(Übersicht!$B$4="NH",IF(Übersicht!$B$5="jetzt",IF(D33="","",D33),IF(F33="","",F33)),IF(Übersicht!$B$5="jetzt",IF(E33="","",E33),IF(G33="","",G33))))) | M33: =IF(L33="","kein Preis",IF(K33<>"","eigener Preis",IF(C33<>"","Händler",IF(IF(Übersicht!$B$4="NH",H33,I33)<Übersicht!$B$6,"dünn","")))) -> kein Preis | N33: https://ahledger.com/items/16203-greater-eternal-essence | O33: NH: keine Zeile
A34: Small Glimmering Shard | B34: VZ | D34: 3.66 | E34: 2.18 | F34: 3.51 | G34: 2.87 | H34: 637 | I34: 1060 | J34: 30.09. | L34: =IF(K34<>"",K34,IF(C34<>"",C34,IF(Übersicht!$B$4="NH",IF(Übersicht!$B$5="jetzt",IF(D34="","",D34),IF(F34="","",F34)),IF(Übersicht!$B$5="jetzt",IF(E34="","",E34),IF(G34="","",G34))))) -> 3.66 | M34: =IF(L34="","kein Preis",IF(K34<>"","eigener Preis",IF(C34<>"","Händler",IF(IF(Übersicht!$B$4="NH",H34,I34)<Übersicht!$B$6,"dünn","")))) | N34: https://ahledger.com/items/10978-small-glimmering-shard
A35: Large Glimmering Shard | B35: VZ | D35: 78.99 | E35: 62 | F35: 111.64 | G35: 85.88 | H35: 121 | I35: 291 | J35: 30.09. | L35: =IF(K35<>"",K35,IF(C35<>"",C35,IF(Übersicht!$B$4="NH",IF(Übersicht!$B$5="jetzt",IF(D35="","",D35),IF(F35="","",F35)),IF(Übersicht!$B$5="jetzt",IF(E35="","",E35),IF(G35="","",G35))))) -> 78.99 | M35: =IF(L35="","kein Preis",IF(K35<>"","eigener Preis",IF(C35<>"","Händler",IF(IF(Übersicht!$B$4="NH",H35,I35)<Übersicht!$B$6,"dünn","")))) | N35: https://ahledger.com/items/11084-large-glimmering-shard
A36: Small Glowing Shard | B36: VZ | D36: 75.99 | E36: 73 | F36: 184.38 | G36: 198.99 | H36: 10 | I36: 7 | J36: 30.09. | L36: =IF(K36<>"",K36,IF(C36<>"",C36,IF(Übersicht!$B$4="NH",IF(Übersicht!$B$5="jetzt",IF(D36="","",D36),IF(F36="","",F36)),IF(Übersicht!$B$5="jetzt",IF(E36="","",E36),IF(G36="","",G36))))) -> 75.99 | M36: =IF(L36="","kein Preis",IF(K36<>"","eigener Preis",IF(C36<>"","Händler",IF(IF(Übersicht!$B$4="NH",H36,I36)<Übersicht!$B$6,"dünn","")))) -> dünn | N36: https://ahledger.com/items/11138-small-glowing-shard
A37: Large Glowing Shard | B37: VZ | D37: 700 | E37: 580.99 | F37: 938.92 | G37: 853.02 | H37: 6 | I37: 33 | J37: 30.09. | L37: =IF(K37<>"",K37,IF(C37<>"",C37,IF(Übersicht!$B$4="NH",IF(Übersicht!$B$5="jetzt",IF(D37="","",D37),IF(F37="","",F37)),IF(Übersicht!$B$5="jetzt",IF(E37="","",E37),IF(G37="","",G37))))) -> 700 | M37: =IF(L37="","kein Preis",IF(K37<>"","eigener Preis",IF(C37<>"","Händler",IF(IF(Übersicht!$B$4="NH",H37,I37)<Übersicht!$B$6,"dünn","")))) -> dünn | N37: https://ahledger.com/items/11139-large-glowing-shard
A38: Small Radiant Shard | B38: VZ | D38: 799.98 | E38: 498 | F38: 592.74 | G38: 918.75 | H38: 33 | I38: 81 | J38: 12.10. | L38: =IF(K38<>"",K38,IF(C38<>"",C38,IF(Übersicht!$B$4="NH",IF(Übersicht!$B$5="jetzt",IF(D38="","",D38),IF(F38="","",F38)),IF(Übersicht!$B$5="jetzt",IF(E38="","",E38),IF(G38="","",G38))))) -> 799.98 | M38: =IF(L38="","kein Preis",IF(K38<>"","eigener Preis",IF(C38<>"","Händler",IF(IF(Übersicht!$B$4="NH",H38,I38)<Übersicht!$B$6,"dünn","")))) -> dünn | N38: https://ahledger.com/items/11177-small-radiant-shard
A39: Large Radiant Shard | B39: VZ | D39: 1149 | E39: 1099 | F39: 1025 | G39: 1449 | H39: 16 | I39: 77 | J39: 12.10. | L39: =IF(K39<>"",K39,IF(C39<>"",C39,IF(Übersicht!$B$4="NH",IF(Übersicht!$B$5="jetzt",IF(D39="","",D39),IF(F39="","",F39)),IF(Übersicht!$B$5="jetzt",IF(E39="","",E39),IF(G39="","",G39))))) -> 1149 | M39: =IF(L39="","kein Preis",IF(K39<>"","eigener Preis",IF(C39<>"","Händler",IF(IF(Übersicht!$B$4="NH",H39,I39)<Übersicht!$B$6,"dünn","")))) -> dünn | N39: https://ahledger.com/items/11178-large-radiant-shard
A40: Small Brilliant Shard | B40: VZ | D40: 488 | E40: 375 | F40: 700 | G40: 465.05 | H40: 4 | I40: 4 | J40: 12.10. | L40: =IF(K40<>"",K40,IF(C40<>"",C40,IF(Übersicht!$B$4="NH",IF(Übersicht!$B$5="jetzt",IF(D40="","",D40),IF(F40="","",F40)),IF(Übersicht!$B$5="jetzt",IF(E40="","",E40),IF(G40="","",G40))))) -> 488 | M40: =IF(L40="","kein Preis",IF(K40<>"","eigener Preis",IF(C40<>"","Händler",IF(IF(Übersicht!$B$4="NH",H40,I40)<Übersicht!$B$6,"dünn","")))) -> dünn | N40: https://ahledger.com/items/14343-small-brilliant-shard
...

Sheet Bedarf
A1: Bedarf nach Wowhead-Route (Classic Era), Schritt für Schritt. Kosten = Menge × Rechenpreis aus Blatt Preise.
A2: Beruf | B2: Band | C2: Fertigkeit | D2: Rezept | E2: Material | F2: Menge | G2: Preis (s) | H2: Kosten (s) | I2: ohne Preis | J2: dünner Markt | K2: Bemerkung
A3: LW | B3: 1-100 | C3: 1-30 | D3: Light Leather x30 | E3: Ruined Leather Scraps | F3: 90 | G3: =IFERROR(INDEX(Preise!$L$3:$L$53,MATCH(E3,Preise!$A$3:$A$53,0)),"") -> 0.25 | H3: =IF(G3="","",F3*G3) -> 22.5 | I3: =IF(G3="",1,0) -> 0 | J3: =IF(IFERROR(INDEX(Preise!$M$3:$M$53,MATCH(E3,Preise!$A$3:$A$53,0)),"")="dünn",1,0) -> 0
A4: LW | B4: 1-100 | C4: 30-45 | D4: Light Armor Kit x18 | E4: Light Leather | F4: 18 | G4: =IFERROR(INDEX(Preise!$L$3:$L$53,MATCH(E4,Preise!$A$3:$A$53,0)),"") -> 0.5 | H4: =IF(G4="","",F4*G4) -> 9 | I4: =IF(G4="",1,0) -> 0 | J4: =IF(IFERROR(INDEX(Preise!$M$3:$M$53,MATCH(E4,Preise!$A$3:$A$53,0)),"")="dünn",1,0) -> 0
A5: LW | B5: 1-100 | C5: 45-55 | D5: Cured Light Hide x10 | E5: Light Hide | F5: 10 | G5: =IFERROR(INDEX(Preise!$L$3:$L$53,MATCH(E5,Preise!$A$3:$A$53,0)),"") -> 0.69 | H5: =IF(G5="","",F5*G5) -> 6.9 | I5: =IF(G5="",1,0) -> 0 | J5: =IF(IFERROR(INDEX(Preise!$M$3:$M$53,MATCH(E5,Preise!$A$3:$A$53,0)),"")="dünn",1,0) -> 0
A6: LW | B6: 1-100 | C6: 45-55 | D6: ↳ Cured Light Hide x10 | E6: Salt | F6: 10 | G6: =IFERROR(INDEX(Preise!$L$3:$L$53,MATCH(E6,Preise!$A$3:$A$53,0)),"") -> 0.5 | H6: =IF(G6="","",F6*G6) -> 5 | I6: =IF(G6="",1,0) -> 0 | J6: =IF(IFERROR(INDEX(Preise!$M$3:$M$53,MATCH(E6,Preise!$A$3:$A$53,0)),"")="dünn",1,0) -> 0
A7: LW | B7: 1-100 | C7: 55-85 | D7: Embossed Leather Gloves x30 | E7: Light Leather | F7: 90 | G7: =IFERROR(INDEX(Preise!$L$3:$L$53,MATCH(E7,Preise!$A$3:$A$53,0)),"") -> 0.5 | H7: =IF(G7="","",F7*G7) -> 45 | I7: =IF(G7="",1,0) -> 0 | J7: =IF(IFERROR(INDEX(Preise!$M$3:$M$53,MATCH(E7,Preise!$A$3:$A$53,0)),"")="dünn",1,0) -> 0 | K7: in Forever grün (entzauberbar)
A8: LW | B8: 1-100 | C8: 55-85 | D8: ↳ Embossed Leather Gloves x30 | E8: Coarse Thread | F8: 60 | G8: =IFERROR(INDEX(Preise!$L$3:$L$53,MATCH(E8,Preise!$A$3:$A$53,0)),"") -> 0.1 | H8: =IF(G8="","",F8*G8) -> 6 | I8: =IF(G8="",1,0) -> 0 | J8: =IF(IFERROR(INDEX(Preise!$M$3:$M$53,MATCH(E8,Preise!$A$3:$A$53,0)),"")="dünn",1,0) -> 0
A9: LW | B9: 1-100 | C9: 85-100 | D9: Fine Leather Belt x15 (aufheben) | E9: Light Leather | F9: 90 | G9: =IFERROR(INDEX(Preise!$L$3:$L$53,MATCH(E9,Preise!$A$3:$A$53,0)),"") -> 0.5 | H9: =IF(G9="","",F9*G9) -> 45 | I9: =IF(G9="",1,0) -> 0 | J9: =IF(IFERROR(INDEX(Preise!$M$3:$M$53,MATCH(E9,Preise!$A$3:$A$53,0)),"")="dünn",1,0) -> 0 | K9: werden bei 135-150 verbraucht
A10: LW | B10: 1-100 | C10: 85-100 | D10: ↳ Fine Leather Belt x15 (aufheben) | E10: Coarse Thread | F10: 30 | G10: =IFERROR(INDEX(Preise!$L$3:$L$53,MATCH(E10,Preise!$A$3:$A$53,0)),"") -> 0.1 | H10: =IF(G10="","",F10*G10) -> 3 | I10: =IF(G10="",1,0) -> 0 | J10: =IF(IFERROR(INDEX(Preise!$M$3:$M$53,MATCH(E10,Preise!$A$3:$A$53,0)),"")="dünn",1,0) -> 0
A11: LW | B11: 100-150 | C11: 100-115 | D11: Cured Medium Hide x15 (aufheben) | E11: Medium Hide | F11: 15 | G11: =IFERROR(INDEX(Preise!$L$3:$L$53,MATCH(E11,Preise!$A$3:$A$53,0)),"") -> 8.88 | H11: =IF(G11="","",F11*G11) -> 133.2 | I11: =IF(G11="",1,0) -> 0 | J11: =IF(IFERROR(INDEX(Preise!$M$3:$M$53,MATCH(E11,Preise!$A$3:$A$53,0)),"")="dünn",1,0) -> 0 | K11: werden bei 135-150 verbraucht
A12: LW | B12: 100-150 | C12: 100-115 | D12: ↳ Cured Medium Hide x15 (aufheben) | E12: Salt | F12: 15 | G12: =IFERROR(INDEX(Preise!$L$3:$L$53,MATCH(E12,Preise!$A$3:$A$53,0)),"") -> 0.5 | H12: =IF(G12="","",F12*G12) -> 7.5 | I12: =IF(G12="",1,0) -> 0 | J12: =IF(IFERROR(INDEX(Preise!$M$3:$M$53,MATCH(E12,Preise!$A$3:$A$53,0)),"")="dünn",1,0) -> 0
A13: LW | B13: 100-150 | C13: 115-125 | D13: Dark Leather Boots x10 | E13: Medium Leather | F13: 40 | G13: =IFERROR(INDEX(Preise!$L$3:$L$53,MATCH(E13,Preise!$A$3:$A$53,0)),"") -> 1.91 | H13: =IF(G13="","",F13*G13) -> 76.4 | I13: =IF(G13="",1,0) -> 0 | J13: =IF(IFERROR(INDEX(Preise!$M$3:$M$53,MATCH(E13,Preise!$A$3:$A$53,0)),"")="dünn",1,0) -> 0
A14: LW | B14: 100-150 | C14: 115-125 | D14: ↳ Dark Leather Boots x10 | E14: Fine Thread | F14: 20 | G14: =IFERROR(INDEX(Preise!$L$3:$L$53,MATCH(E14,Preise!$A$3:$A$53,0)),"") -> 1 | H14: =IF(G14="","",F14*G14) -> 20 | I14: =IF(G14="",1,0) -> 0 | J14: =IF(IFERROR(INDEX(Preise!$M$3:$M$53,MATCH(E14,Preise!$A$3:$A$53,0)),"")="dünn",1,0) -> 0
A15: LW | B15: 100-150 | C15: 115-125 | D15: ↳ Dark Leather Boots x10 | E15: Gray Dye | F15: 10 | G15: =IFERROR(INDEX(Preise!$L$3:$L$53,MATCH(E15,Preise!$A$3:$A$53,0)),"") -> 3.5 | H15: =IF(G15="","",F15*G15) -> 35 | I15: =IF(G15="",1,0) -> 0 | J15: =IF(IFERROR(INDEX(Preise!$M$3:$M$53,MATCH(E15,Preise!$A$3:$A$53,0)),"")="dünn",1,0) -> 0
A16: LW | B16: 100-150 | C16: 125-135 | D16: Dark Leather Boots x12 | E16: Medium Leather | F16: 48 | G16: =IFERROR(INDEX(Preise!$L$3:$L$53,MATCH(E16,Preise!$A$3:$A$53,0)),"") -> 1.91 | H16: =IF(G16="","",F16*G16) -> 91.68 | I16: =IF(G16="",1,0) -> 0 | J16: =IF(IFERROR(INDEX(Preise!$M$3:$M$53,MATCH(E16,Preise!$A$3:$A$53,0)),"")="dünn",1,0) -> 0
A17: LW | B17: 100-150 | C17: 125-135 | D17: ↳ Dark Leather Boots x12 | E17: Fine Thread | F17: 24 | G17: =IFERROR(INDEX(Preise!$L$3:$L$53,MATCH(E17,Preise!$A$3:$A$53,0)),"") -> 1 | H17: =IF(G17="","",F17*G17) -> 24 | I17: =IF(G17="",1,0) -> 0 | J17: =IF(IFERROR(INDEX(Preise!$M$3:$M$53,MATCH(E17,Preise!$A$3:$A$53,0)),"")="dünn",1,0) -> 0
A18: LW | B18: 100-150 | C18: 125-135 | D18: ↳ Dark Leather Boots x12 | E18: Gray Dye | F18: 12 | G18: =IFERROR(INDEX(Preise!$L$3:$L$53,MATCH(E18,Preise!$A$3:$A$53,0)),"") -> 3.5 | H18: =IF(G18="","",F18*G18) -> 42 | I18: =IF(G18="",1,0) -> 0 | J18: =IF(IFERROR(INDEX(Preise!$M$3:$M$53,MATCH(E18,Preise!$A$3:$A$53,0)),"")="dünn",1,0) -> 0
A19: LW | B19: 100-150 | C19: 135-150 | D19: Dark Leather Belt x15 (+15 Fine Leather Belt, +15 Cured Medium Hide) | E19: Fine Thread | F19: 30 | G19: =IFERROR(INDEX(Preise!$L$3:$L$53,MATCH(E19,Preise!$A$3:$A$53,0)),"") -> 1 | H19: =IF(G19="","",F19*G19) -> 30 | I19: =IF(G19="",1,0) -> 0 | J19: =IF(IFERROR(INDEX(Preise!$M$3:$M$53,MATCH(E19,Preise!$A$3:$A$53,0)),"")="dünn",1,0) -> 0
A20: LW | B20: 100-150 | C20: 135-150 | D20: ↳ Dark Leather Belt x15 (+15 Fine Leather Belt, +15 Cured Medium Hide) | E20: Gray Dye | F20: 15 | G20: =IFERROR(INDEX(Preise!$L$3:$L$53,MATCH(E20,Preise!$A$3:$A$53,0)),"") -> 3.5 | H20: =IF(G20="","",F20*G20) -> 52.5 | I20: =IF(G20="",1,0) -> 0 | J20: =IF(IFERROR(INDEX(Preise!$M$3:$M$53,MATCH(E20,Preise!$A$3:$A$53,0)),"")="dünn",1,0) -> 0
A21: LW | B21: 150-200 | C21: 150-155 | D21: Heavy Leather x5 (aufheben) | E21: Medium Leather | F21: 25 | G21: =IFERROR(INDEX(Preise!$L$3:$L$53,MATCH(E21,Preise!$A$3:$A$53,0)),"") -> 1.91 | H21: =IF(G21="","",F21*G21) -> 47.75 | I21: =IF(G21="",1,0) -> 0 | J21: =IF(IFERROR(INDEX(Preise!$M$3:$M$53,MATCH(E21,Preise!$A$3:$A$53,0)),"")="dünn",1,0) -> 0 | K21: Wowhead-Liste kauft trotzdem 230 Heavy Leather
A22: LW | B22: 150-200 | C22: 155-160 | D22: Cured Heavy Hide x5 (aufheben) | E22: Heavy Hide | F22: 5 | G22: =IFERROR(INDEX(Preise!$L$3:$L$53,MATCH(E22,Preise!$A$3:$A$53,0)),"") -> 35.4 | H22: =IF(G22="","",F22*G22) -> 177 | I22: =IF(G22="",1,0) -> 0 | J22: =IF(IFERROR(INDEX(Preise!$M$3:$M$53,MATCH(E22,Preise!$A$3:$A$53,0)),"")="dünn",1,0) -> 0
A23: LW | B23: 150-200 | C23: 155-160 | D23: ↳ Cured Heavy Hide x5 (aufheben) | E23: Salt | F23: 15 | G23: =IFERROR(INDEX(Preise!$L$3:$L$53,MATCH(E23,Preise!$A$3:$A$53,0)),"") -> 0.5 | H23: =IF(G23="","",F23*G23) -> 7.5 | I23: =IF(G23="",1,0) -> 0 | J23: =IF(IFERROR(INDEX(Preise!$M$3:$M$53,MATCH(E23,Preise!$A$3:$A$53,0)),"")="dünn",1,0) -> 0
A24: LW | B24: 150-200 | C24: 160-180 | D24: Heavy Armor Kit x22 | E24: Heavy Leather | F24: 110 | G24: =IFERROR(INDEX(Preise!$L$3:$L$53,MATCH(E24,Preise!$A$3:$A$53,0)),"") -> 11.98 | H24: =IF(G24="","",F24*G24) -> 1317.8 | I24: =IF(G24="",1,0) -> 0 | J24: =IF(IFERROR(INDEX(Preise!$M$3:$M$53,MATCH(E24,Preise!$A$3:$A$53,0)),"")="dünn",1,0) -> 0
A25: LW | B25: 150-200 | C25: 160-180 | D25: ↳ Heavy Armor Kit x22 | E25: Fine Thread | F25: 22 | G25: =IFERROR(INDEX(Preise!$L$3:$L$53,MATCH(E25,Preise!$A$3:$A$53,0)),"") -> 1 | H25: =IF(G25="","",F25*G25) -> 22 | I25: =IF(G25="",1,0) -> 0 | J25: =IF(IFERROR(INDEX(Preise!$M$3:$M$53,MATCH(E25,Preise!$A$3:$A$53,0)),"")="dünn",1,0) -> 0
A26: LW | B26: 150-200 | C26: 180-190 | D26: Barbaric Shoulders x10 (+10 Cured Heavy Hide) | E26: Heavy Leather | F26: 80 | G26: =IFERROR(INDEX(Preise!$L$3:$L$53,MATCH(E26,Preise!$A$3:$A$53,0)),"") -> 11.98 | H26: =IF(G26="","",F26*G26) -> 958.4 | I26: =IF(G26="",1,0) -> 0 | J26: =IF(IFERROR(INDEX(Preise!$M$3:$M$53,MATCH(E26,Preise!$A$3:$A$53,0)),"")="dünn",1,0) -> 0
A27: LW | B27: 150-200 | C27: 180-190 | D27: ↳ Barbaric Shoulders x10 (+10 Cured Heavy Hide) | E27: Fine Thread | F27: 20 | G27: =IFERROR(INDEX(Preise!$L$3:$L$53,MATCH(E27,Preise!$A$3:$A$53,0)),"") -> 1 | H27: =IF(G27="","",F27*G27) -> 20 | I27: =IF(G27="",1,0) -> 0 | J27: =IF(IFERROR(INDEX(Preise!$M$3:$M$53,MATCH(E27,Preise!$A$3:$A$53,0)),"")="dünn",1,0) -> 0
A28: LW | B28: 150-200 | C28: 190-200 | D28: Guardian Gloves x10 (+10 Cured Heavy Hide) | E28: Heavy Leather | F28: 40 | G28: =IFERROR(INDEX(Preise!$L$3:$L$53,MATCH(E28,Preise!$A$3:$A$53,0)),"") -> 11.98 | H28: =IF(G28="","",F28*G28) -> 479.2 | I28: =IF(G28="",1,0) -> 0 | J28: =IF(IFERROR(INDEX(Preise!$M$3:$M$53,MATCH(E28,Preise!$A$3:$A$53,0)),"")="dünn",1,0) -> 0
A29: LW | B29: 150-200 | C29: 190-200 | D29: ↳ Guardian Gloves x10 (+10 Cured Heavy Hide) | E29: Silken Thread | F29: 10 | G29: =IFERROR(INDEX(Preise!$L$3:$L$53,MATCH(E29,Preise!$A$3:$A$53,0)),"") -> 5 | H29: =IF(G29="","",F29*G29) -> 50 | I29: =IF(G29="",1,0) -> 0 | J29: =IF(IFERROR(INDEX(Preise!$M$3:$M$53,MATCH(E29,Preise!$A$3:$A$53,0)),"")="dünn",1,0) -> 0
A30: LW | B30: 150-200 | C30: Korrektur | D30: Cured Heavy Hide x15 (fehlen in der Route: 20 gebraucht, 5 hergestellt) | E30: Heavy Hide | F30: 15 | G30: =IFERROR(INDEX(Preise!$L$3:$L$53,MATCH(E30,Preise!$A$3:$A$53,0)),"") -> 35.4 | H30: =IF(G30="","",F30*G30) -> 531 | I30: =IF(G30="",1,0) -> 0 | J30: =IF(IFERROR(INDEX(Preise!$M$3:$M$53,MATCH(E30,Preise!$A$3:$A$53,0)),"")="dünn",1,0) -> 0 | K30: von mir ergänzt, nicht von Wowhead
A31: LW | B31: 150-200 | C31: Korrektur | D31: ↳ Cured Heavy Hide x15 (fehlen in der Route: 20 gebraucht, 5 hergestellt) | E31: Salt | F31: 45 | G31: =IFERROR(INDEX(Preise!$L$3:$L$53,MATCH(E31,Preise!$A$3:$A$53,0)),"") -> 0.5 | H31: =IF(G31="","",F31*G31) -> 22.5 | I31: =IF(G31="",1,0) -> 0 | J31: =IF(IFERROR(INDEX(Preise!$M$3:$M$53,MATCH(E31,Preise!$A$3:$A$53,0)),"")="dünn",1,0) -> 0
A32: LW | B32: 200-250 | C32: 200-220 | D32: Thick Armor Kit x20 | E32: Thick Leather | F32: 100 | G32: =IFERROR(INDEX(Preise!$L$3:$L$53,MATCH(E32,Preise!$A$3:$A$53,0)),"") -> 35.79 | H32: =IF(G32="","",F32*G32) -> 3579 | I32: =IF(G32="",1,0) -> 0 | J32: =IF(IFERROR(INDEX(Preise!$M$3:$M$53,MATCH(E32,Preise!$A$3:$A$53,0)),"")="dünn",1,0) -> 0
A33: LW | B33: 200-250 | C33: 200-220 | D33: ↳ Thick Armor Kit x20 | E33: Silken Thread | F33: 20 | G33: =IFERROR(INDEX(Preise!$L$3:$L$53,MATCH(E33,Preise!$A$3:$A$53,0)),"") -> 5 | H33: =IF(G33="","",F33*G33) -> 100 | I33: =IF(G33="",1,0) -> 0 | J33: =IF(IFERROR(INDEX(Preise!$M$3:$M$53,MATCH(E33,Preise!$A$3:$A$53,0)),"")="dünn",1,0) -> 0
A34: LW | B34: 200-250 | C34: 220-230 | D34: Nightscape Headband x11 | E34: Thick Leather | F34: 55 | G34: =IFERROR(INDEX(Preise!$L$3:$L$53,MATCH(E34,Preise!$A$3:$A$53,0)),"") -> 35.79 | H34: =IF(G34="","",F34*G34) -> 1968.45 | I34: =IF(G34="",1,0) -> 0 | J34: =IF(IFERROR(INDEX(Preise!$M$3:$M$53,MATCH(E34,Preise!$A$3:$A$53,0)),"")="dünn",1,0) -> 0 | K34: Wowhead: 2 für Tribal aufheben
A35: LW | B35: 200-250 | C35: 220-230 | D35: ↳ Nightscape Headband x11 | E35: Silken Thread | F35: 22 | G35: =IFERROR(INDEX(Preise!$L$3:$L$53,MATCH(E35,Preise!$A$3:$A$53,0)),"") -> 5 | H35: =IF(G35="","",F35*G35) -> 110 | I35: =IF(G35="",1,0) -> 0 | J35: =IF(IFERROR(INDEX(Preise!$M$3:$M$53,MATCH(E35,Preise!$A$3:$A$53,0)),"")="dünn",1,0) -> 0
A36: LW | B36: 200-250 | C36: 230-250 | D36: Nightscape Pants x20 | E36: Thick Leather | F36: 280 | G36: =IFERROR(INDEX(Preise!$L$3:$L$53,MATCH(E36,Preise!$A$3:$A$53,0)),"") -> 35.79 | H36: =IF(G36="","",F36*G36) -> 10021.2 | I36: =IF(G36="",1,0) -> 0 | J36: =IF(IFERROR(INDEX(Preise!$M$3:$M$53,MATCH(E36,Preise!$A$3:$A$53,0)),"")="dünn",1,0) -> 0 | K36: Wowhead: 2 für Tribal aufheben
A37: LW | B37: 200-250 | C37: 230-250 | D37: ↳ Nightscape Pants x20 | E37: Silken Thread | F37: 80 | G37: =IFERROR(INDEX(Preise!$L$3:$L$53,MATCH(E37,Preise!$A$3:$A$53,0)),"") -> 5 | H37: =IF(G37="","",F37*G37) -> 400 | I37: =IF(G37="",1,0) -> 0 | J37: =IF(IFERROR(INDEX(Preise!$M$3:$M$53,MATCH(E37,Preise!$A$3:$A$53,0)),"")="dünn",1,0) -> 0
A38: LW | B38: 250-300 | C38: 250-260 | D38: Rugged Armor Kit x12 | E38: Rugged Leather | F38: 60 | G38: =IFERROR(INDEX(Preise!$L$3:$L$53,MATCH(E38,Preise!$A$3:$A$53,0)),"") -> 19.02 | H38: =IF(G38="","",F38*G38) -> 1141.2 | I38: =IF(G38="",1,0) -> 0 | J38: =IF(IFERROR(INDEX(Preise!$M$3:$M$53,MATCH(E38,Preise!$A$3:$A$53,0)),"")="dünn",1,0) -> 0
A39: LW | B39: 250-300 | C39: 260-290 | D39: Wicked Leather Gauntlets x32 | E39: Rugged Leather | F39: 256 | G39: =IFERROR(INDEX(Preise!$L$3:$L$53,MATCH(E39,Preise!$A$3:$A$53,0)),"") -> 19.02 | H39: =IF(G39="","",F39*G39) -> 4869.12 | I39: =IF(G39="",1,0) -> 0 | J39: =IF(IFERROR(INDEX(Preise!$M$3:$M$53,MATCH(E39,Preise!$A$3:$A$53,0)),"")="dünn",1,0) -> 0 | K39: Muster vom Händler
A40: LW | B40: 250-300 | C40: 260-290 | D40: ↳ Wicked Leather Gauntlets x32 | E40: Black Dye | F40: 32 | G40: =IFERROR(INDEX(Preise!$L$3:$L$53,MATCH(E40,Preise!$A$3:$A$53,0)),"") -> 10 | H40: =IF(G40="","",F40*G40) -> 320 | I40: =IF(G40="",1,0) -> 0 | J40: =IF(IFERROR(INDEX(Preise!$M$3:$M$53,MATCH(E40,Preise!$A$3:$A$53,0)),"")="dünn",1,0) -> 0
...

Sheet Kreislauf
A1: Kreislauf: Was die grünen LW-Teile beim Entzaubern liefern (Forever-Stufen, Tabelle wow-professions) und wie viel vom VZ-Bedarf das deckt
A2: Mengen pro Teil = Chance × Mittelwert der Spanne (Annahme: gleich verteilt). Werte in Silber, Deckung gegen den VZ-Bedarf aus Blatt Bedarf.
A3: Chance Staub | B3: 0.75
A4: Chance Essenz | B4: 0.2
A5: Chance Splitter | B5: 0.04 | C5: 3–5 % laut Tabelle, Mitte genommen
A7: Stufe von | B7: Stufe bis | C7: Staub | D7: Staub min | E7: Staub max | F7: Essenz | G7: Essenz min | H7: Essenz max | I7: Splitter
A8: 1 | B8: 10 | C8: Strange Dust | D8: 1 | E8: 2 | F8: Lesser Magic Essence | G8: 1 | H8: 2 | I8: –
A9: 11 | B9: 15 | C9: Strange Dust | D9: 2 | E9: 3 | F9: Greater Magic Essence | G9: 1 | H9: 2 | I9: Small Glimmering Shard
A10: 16 | B10: 20 | C10: Strange Dust | D10: 4 | E10: 6 | F10: Lesser Astral Essence | G10: 1 | H10: 2 | I10: Small Glimmering Shard
A11: 21 | B11: 25 | C11: Soul Dust | D11: 1 | E11: 2 | F11: Greater Astral Essence | G11: 1 | H11: 2 | I11: Large Glimmering Shard
A12: 26 | B12: 30 | C12: Soul Dust | D12: 2 | E12: 5 | F12: Lesser Mystic Essence | G12: 1 | H12: 2 | I12: Small Glowing Shard
A13: 31 | B13: 35 | C13: Vision Dust | D13: 1 | E13: 2 | F13: Greater Mystic Essence | G13: 1 | H13: 2 | I13: Large Glowing Shard
A14: 36 | B14: 40 | C14: Vision Dust | D14: 2 | E14: 5 | F14: Lesser Nether Essence | G14: 1 | H14: 2 | I14: Small Radiant Shard
A15: 41 | B15: 45 | C15: Dream Dust | D15: 1 | E15: 2 | F15: Greater Nether Essence | G15: 1 | H15: 2 | I15: Large Radiant Shard
A16: 46 | B16: 50 | C16: Dream Dust | D16: 2 | E16: 5 | F16: Lesser Eternal Essence | G16: 1 | H16: 2 | I16: Small Brilliant Shard
A17: 51 | B17: 55 | C17: Illusion Dust | D17: 1 | E17: 2 | F17: Greater Eternal Essence | G17: 1 | H17: 2 | I17: Large Brilliant Shard
A18: 56 | B18: 60 | C18: Illusion Dust | D18: 2 | E18: 5 | F18: Greater Eternal Essence | G18: 1 | H18: 3 | I18: Large Brilliant Shard
A20: Grünes LW-Teil | B20: benötigte Stufe | C20: Tabellenzeile | D20: Staub | E20: Staub/Teil | F20: Essenz | G20: Essenz/Teil | H20: Splitter | I20: Splitter/Teil | J20: Entzauberungswert (s) | K20: Materialkosten (s) | L20: Händlerpreis (s) | M20: Entzaubern − Kosten (s) | N20: Händler − Kosten (s) | O20: Anzahl in Wowhead-Route | P20: Reagenz 1 | Q20: Menge | R20: Reagenz 2 | S20: Menge | T20: Reagenz 3 | U20: Menge | V20: Reagenz 4 | W20: Menge | X20: Reagenz 5 | Y20: Menge | Z20: Reagenz 6 | AA20: Menge | AB20: Preise fehlen | AC20: Reagenzien laut | AD20: Item-Seite
A21: Embossed Leather Gloves | B21: 8 | C21: =MATCH(B21,$A$8:$A$18,1) -> 1 | D21: =INDEX($C$8:$C$18,C21) -> Strange Dust | E21: =$B$3*(INDEX($D$8:$D$18,C21)+INDEX($E$8:$E$18,C21))/2 -> 1.125 | F21: =INDEX($F$8:$F$18,C21) -> Lesser Magic Essence | G21: =$B$4*(INDEX($G$8:$G$18,C21)+INDEX($H$8:$H$18,C21))/2 -> 0.3 | H21: =INDEX($I$8:$I$18,C21) -> – | I21: =IF(H21="–",0,$B$5) -> 0 | J21: =IFERROR(E21*INDEX(Preise!$L$3:$L$53,MATCH(D21,Preise!$A$3:$A$53,0)),0)+IFERROR(G21*INDEX(Preise!$L$3:$L$53,MATCH(F21,Preise!$A$3:$A$53,0)),0)+IF(H21="–",0,IFERROR(I21*INDEX(Preise!$L$3:$L$53,MATCH(H21,Preise!$A$3:$A$53,0)),0)) -> 1.152 | K21: =IF(P21="",0,IFERROR(Q21*INDEX(Preise!$L$3:$L$53,MATCH(P21,Preise!$A$3:$A$53,0)),0))+IF(R21="",0,IFERROR(S21*INDEX(Preise!$L$3:$L$53,MATCH(R21,Preise!$A$3:$A$53,0)),0))+IF(T21="",0,IFERROR(U21*INDEX(Preise!$L$3:$L$53,MATCH(T21,Preise!$A$3:$A$53,0)),0))+IF(V21="",0,IFERROR(W21*INDEX(Preise!$L$3:$L$53,MATCH(V21,Preise!$A$3:$A$53,0)),0))+IF(X21="",0,IFERROR(Y21*INDEX(Preise!$L$3:$L$53,MATCH(X21,Preise!$A$3:$A$53,0)),0))+IF(Z21="",0,IFERROR(AA21*INDEX(Preise!$L$3:$L$53,MATCH(Z21,Preise!$A$3:$A$53,0)),0)) -> 1.7 | L21: 0.71 | M21: =J21-K21 -> -0.548 | N21: =L21-K21 -> -0.99 | O21: 30 | P21: Light Leather | Q21: 3 | R21: Coarse Thread | S21: 2 | AB21: =IF(P21="",0,IF(IFERROR(INDEX(Preise!$L$3:$L$53,MATCH(P21,Preise!$A$3:$A$53,0)),"")="",1,0))+IF(R21="",0,IF(IFERROR(INDEX(Preise!$L$3:$L$53,MATCH(R21,Preise!$A$3:$A$53,0)),"")="",1,0))+IF(T21="",0,IF(IFERROR(INDEX(Preise!$L$3:$L$53,MATCH(T21,Preise!$A$3:$A$53,0)),"")="",1,0))+IF(V21="",0,IF(IFERROR(INDEX(Preise!$L$3:$L$53,MATCH(V21,Preise!$A$3:$A$53,0)),"")="",1,0))+IF(X21="",0,IF(IFERROR(INDEX(Preise!$L$3:$L$53,MATCH(X21,Preise!$A$3:$A$53,0)),"")="",1,0))+IF(Z21="",0,IF(IFERROR(INDEX(Preise!$L$3:$L$53,MATCH(Z21,Preise!$A$3:$A$53,0)),"")="",1,0))+IF(IFERROR(INDEX(Preise!$L$3:$L$53,MATCH(D21,Preise!$A$3:$A$53,0)),"")="",1,0)+IF(IFERROR(INDEX(Preise!$L$3:$L$53,MATCH(F21,Preise!$A$3:$A$53,0)),"")="",1,0)+IF(H21="–",0,IF(IFERROR(INDEX(Preise!$L$3:$L$53,MATCH(H21,Preise!$A$3:$A$53,0)),"")="",1,0)) -> 0 | AC21: Wowhead-Route | AD21: https://www.wowhead.com/forever/item=4239/embossed-leather-gloves
A22: Fine Leather Belt | B22: 11 | C22: =MATCH(B22,$A$8:$A$18,1) -> 2 | D22: =INDEX($C$8:$C$18,C22) -> Strange Dust | E22: =$B$3*(INDEX($D$8:$D$18,C22)+INDEX($E$8:$E$18,C22))/2 -> 1.875 | F22: =INDEX($F$8:$F$18,C22) -> Greater Magic Essence | G22: =$B$4*(INDEX($G$8:$G$18,C22)+INDEX($H$8:$H$18,C22))/2 -> 0.3 | H22: =INDEX($I$8:$I$18,C22) -> Small Glimmering Shard | I22: =IF(H22="–",0,$B$5) -> 0.04 | J22: =IFERROR(E22*INDEX(Preise!$L$3:$L$53,MATCH(D22,Preise!$A$3:$A$53,0)),0)+IFERROR(G22*INDEX(Preise!$L$3:$L$53,MATCH(F22,Preise!$A$3:$A$53,0)),0)+IF(H22="–",0,IFERROR(I22*INDEX(Preise!$L$3:$L$53,MATCH(H22,Preise!$A$3:$A$53,0)),0)) -> 2.3094 | K22: =IF(P22="",0,IFERROR(Q22*INDEX(Preise!$L$3:$L$53,MATCH(P22,Preise!$A$3:$A$53,0)),0))+IF(R22="",0,IFERROR(S22*INDEX(Preise!$L$3:$L$53,MATCH(R22,Preise!$A$3:$A$53,0)),0))+IF(T22="",0,IFERROR(U22*INDEX(Preise!$L$3:$L$53,MATCH(T22,Preise!$A$3:$A$53,0)),0))+IF(V22="",0,IFERROR(W22*INDEX(Preise!$L$3:$L$53,MATCH(V22,Preise!$A$3:$A$53,0)),0))+IF(X22="",0,IFERROR(Y22*INDEX(Preise!$L$3:$L$53,MATCH(X22,Preise!$A$3:$A$53,0)),0))+IF(Z22="",0,IFERROR(AA22*INDEX(Preise!$L$3:$L$53,MATCH(Z22,Preise!$A$3:$A$53,0)),0)) -> 3.2 | L22: 1.25 | M22: =J22-K22 -> -0.8906 | N22: =L22-K22 -> -1.95 | O22: 0 | P22: Light Leather | Q22: 6 | R22: Coarse Thread | S22: 2 | AB22: =IF(P22="",0,IF(IFERROR(INDEX(Preise!$L$3:$L$53,MATCH(P22,Preise!$A$3:$A$53,0)),"")="",1,0))+IF(R22="",0,IF(IFERROR(INDEX(Preise!$L$3:$L$53,MATCH(R22,Preise!$A$3:$A$53,0)),"")="",1,0))+IF(T22="",0,IF(IFERROR(INDEX(Preise!$L$3:$L$53,MATCH(T22,Preise!$A$3:$A$53,0)),"")="",1,0))+IF(V22="",0,IF(IFERROR(INDEX(Preise!$L$3:$L$53,MATCH(V22,Preise!$A$3:$A$53,0)),"")="",1,0))+IF(X22="",0,IF(IFERROR(INDEX(Preise!$L$3:$L$53,MATCH(X22,Preise!$A$3:$A$53,0)),"")="",1,0))+IF(Z22="",0,IF(IFERROR(INDEX(Preise!$L$3:$L$53,MATCH(Z22,Preise!$A$3:$A$53,0)),"")="",1,0))+IF(IFERROR(INDEX(Preise!$L$3:$L$53,MATCH(D22,Preise!$A$3:$A$53,0)),"")="",1,0)+IF(IFERROR(INDEX(Preise!$L$3:$L$53,MATCH(F22,Preise!$A$3:$A$53,0)),"")="",1,0)+IF(H22="–",0,IF(IFERROR(INDEX(Preise!$L$3:$L$53,MATCH(H22,Preise!$A$3:$A$53,0)),"")="",1,0)) -> 0 | AC22: Wowhead-Route; alle 15 gehen in Dark Leather Belt | AD22: https://www.wowhead.com/forever/item=4246/fine-leather-belt
A23: Light Leather Pants | B23: 14 | C23: =MATCH(B23,$A$8:$A$18,1) -> 2 | D23: =INDEX($C$8:$C$18,C23) -> Strange Dust | E23: =$B$3*(INDEX($D$8:$D$18,C23)+INDEX($E$8:$E$18,C23))/2 -> 1.875 | F23: =INDEX($F$8:$F$18,C23) -> Greater Magic Essence | G23: =$B$4*(INDEX($G$8:$G$18,C23)+INDEX($H$8:$H$18,C23))/2 -> 0.3 | H23: =INDEX($I$8:$I$18,C23) -> Small Glimmering Shard | I23: =IF(H23="–",0,$B$5) -> 0.04 | J23: =IFERROR(E23*INDEX(Preise!$L$3:$L$53,MATCH(D23,Preise!$A$3:$A$53,0)),0)+IFERROR(G23*INDEX(Preise!$L$3:$L$53,MATCH(F23,Preise!$A$3:$A$53,0)),0)+IF(H23="–",0,IFERROR(I23*INDEX(Preise!$L$3:$L$53,MATCH(H23,Preise!$A$3:$A$53,0)),0)) -> 2.3094 | K23: =IF(P23="",0,IFERROR(Q23*INDEX(Preise!$L$3:$L$53,MATCH(P23,Preise!$A$3:$A$53,0)),0))+IF(R23="",0,IFERROR(S23*INDEX(Preise!$L$3:$L$53,MATCH(R23,Preise!$A$3:$A$53,0)),0))+IF(T23="",0,IFERROR(U23*INDEX(Preise!$L$3:$L$53,MATCH(T23,Preise!$A$3:$A$53,0)),0))+IF(V23="",0,IFERROR(W23*INDEX(Preise!$L$3:$L$53,MATCH(V23,Preise!$A$3:$A$53,0)),0))+IF(X23="",0,IFERROR(Y23*INDEX(Preise!$L$3:$L$53,MATCH(X23,Preise!$A$3:$A$53,0)),0))+IF(Z23="",0,IFERROR(AA23*INDEX(Preise!$L$3:$L$53,MATCH(Z23,Preise!$A$3:$A$53,0)),0)) -> 7.19 | L23: 5.99 | M23: =J23-K23 -> -4.8806 | N23: =L23-K23 -> -1.2 | O23: 0 | P23: Light Leather | Q23: 10 | R23: Light Hide | S23: 1 | T23: Salt | U23: 1 | V23: Fine Thread | W23: 1 | AB23: =IF(P23="",0,IF(IFERROR(INDEX(Preise!$L$3:$L$53,MATCH(P23,Preise!$A$3:$A$53,0)),"")="",1,0))+IF(R23="",0,IF(IFERROR(INDEX(Preise!$L$3:$L$53,MATCH(R23,Preise!$A$3:$A$53,0)),"")="",1,0))+IF(T23="",0,IF(IFERROR(INDEX(Preise!$L$3:$L$53,MATCH(T23,Preise!$A$3:$A$53,0)),"")="",1,0))+IF(V23="",0,IF(IFERROR(INDEX(Preise!$L$3:$L$53,MATCH(V23,Preise!$A$3:$A$53,0)),"")="",1,0))+IF(X23="",0,IF(IFERROR(INDEX(Preise!$L$3:$L$53,MATCH(X23,Preise!$A$3:$A$53,0)),"")="",1,0))+IF(Z23="",0,IF(IFERROR(INDEX(Preise!$L$3:$L$53,MATCH(Z23,Preise!$A$3:$A$53,0)),"")="",1,0))+IF(IFERROR(INDEX(Preise!$L$3:$L$53,MATCH(D23,Preise!$A$3:$A$53,0)),"")="",1,0)+IF(IFERROR(INDEX(Preise!$L$3:$L$53,MATCH(F23,Preise!$A$3:$A$53,0)),"")="",1,0)+IF(H23="–",0,IF(IFERROR(INDEX(Preise!$L$3:$L$53,MATCH(H23,Preise!$A$3:$A$53,0)),"")="",1,0)) -> 0 | AC23: AHledger (Forever); nicht in Wowhead-Route | AD23: https://www.wowhead.com/forever/item=7282/light-leather-pants
A24: Dark Leather Boots | B24: 15 | C24: =MATCH(B24,$A$8:$A$18,1) -> 2 | D24: =INDEX($C$8:$C$18,C24) -> Strange Dust | E24: =$B$3*(INDEX($D$8:$D$18,C24)+INDEX($E$8:$E$18,C24))/2 -> 1.875 | F24: =INDEX($F$8:$F$18,C24) -> Greater Magic Essence | G24: =$B$4*(INDEX($G$8:$G$18,C24)+INDEX($H$8:$H$18,C24))/2 -> 0.3 | H24: =INDEX($I$8:$I$18,C24) -> Small Glimmering Shard | I24: =IF(H24="–",0,$B$5) -> 0.04 | J24: =IFERROR(E24*INDEX(Preise!$L$3:$L$53,MATCH(D24,Preise!$A$3:$A$53,0)),0)+IFERROR(G24*INDEX(Preise!$L$3:$L$53,MATCH(F24,Preise!$A$3:$A$53,0)),0)+IF(H24="–",0,IFERROR(I24*INDEX(Preise!$L$3:$L$53,MATCH(H24,Preise!$A$3:$A$53,0)),0)) -> 2.3094 | K24: =IF(P24="",0,IFERROR(Q24*INDEX(Preise!$L$3:$L$53,MATCH(P24,Preise!$A$3:$A$53,0)),0))+IF(R24="",0,IFERROR(S24*INDEX(Preise!$L$3:$L$53,MATCH(R24,Preise!$A$3:$A$53,0)),0))+IF(T24="",0,IFERROR(U24*INDEX(Preise!$L$3:$L$53,MATCH(T24,Preise!$A$3:$A$53,0)),0))+IF(V24="",0,IFERROR(W24*INDEX(Preise!$L$3:$L$53,MATCH(V24,Preise!$A$3:$A$53,0)),0))+IF(X24="",0,IFERROR(Y24*INDEX(Preise!$L$3:$L$53,MATCH(X24,Preise!$A$3:$A$53,0)),0))+IF(Z24="",0,IFERROR(AA24*INDEX(Preise!$L$3:$L$53,MATCH(Z24,Preise!$A$3:$A$53,0)),0)) -> 13.14 | L24: 3.07 | M24: =J24-K24 -> -10.8306 | N24: =L24-K24 -> -10.07 | O24: 22 | P24: Medium Leather | Q24: 4 | R24: Fine Thread | S24: 2 | T24: Gray Dye | U24: 1 | AB24: =IF(P24="",0,IF(IFERROR(INDEX(Preise!$L$3:$L$53,MATCH(P24,Preise!$A$3:$A$53,0)),"")="",1,0))+IF(R24="",0,IF(IFERROR(INDEX(Preise!$L$3:$L$53,MATCH(R24,Preise!$A$3:$A$53,0)),"")="",1,0))+IF(T24="",0,IF(IFERROR(INDEX(Preise!$L$3:$L$53,MATCH(T24,Preise!$A$3:$A$53,0)),"")="",1,0))+IF(V24="",0,IF(IFERROR(INDEX(Preise!$L$3:$L$53,MATCH(V24,Preise!$A$3:$A$53,0)),"")="",1,0))+IF(X24="",0,IF(IFERROR(INDEX(Preise!$L$3:$L$53,MATCH(X24,Preise!$A$3:$A$53,0)),"")="",1,0))+IF(Z24="",0,IF(IFERROR(INDEX(Preise!$L$3:$L$53,MATCH(Z24,Preise!$A$3:$A$53,0)),"")="",1,0))+IF(IFERROR(INDEX(Preise!$L$3:$L$53,MATCH(D24,Preise!$A$3:$A$53,0)),"")="",1,0)+IF(IFERROR(INDEX(Preise!$L$3:$L$53,MATCH(F24,Preise!$A$3:$A$53,0)),"")="",1,0)+IF(H24="–",0,IF(IFERROR(INDEX(Preise!$L$3:$L$53,MATCH(H24,Preise!$A$3:$A$53,0)),"")="",1,0)) -> 0 | AC24: Wowhead-Route | AD24: https://www.wowhead.com/forever/item=2315/dark-leather-boots
